<?xml version="1.0"?>
<robot xmlns:xacro="http://wiki.ros.org/xacro">
  <!--
    Base UR robot series xacro macro.

    NOTE: this is NOT a URDF. It cannot directly be loaded by consumers
    expecting a flattened '.urdf' file. See the top-level '.xacro' for that
    (but note: that .xacro must still be processed by the xacro command).

    For use in '.launch' files: use one of the 'load_urX.launch' convenience
    launch files.

    This file models the base kinematic chain of a UR robot, which then gets
    parameterised by various configuration files to convert it into a UR3(e),
    UR5(e), UR7e, UR10(e), UR12e UR16e, UR15, UR20 or UR30.

    NOTE: the default kinematic parameters (ie: link lengths, frame locations,
    offets, etc) do not correspond to any particular robot. They are defaults
    only. There WILL be non-zero offsets between the Forward Kinematics results
    in TF (ie: robot_state_publisher) and the values reported by the Teach
    Pendant.

    For accurate (and robot-specific) transforms, the 'kinematics_parameters_file'
    parameter MUST point to a .yaml file containing the appropriate values for
    the targetted robot.

    If using the UniversalRobots/Universal_Robots_ROS_Driver, follow the steps
    described in the readme of that repository to extract the kinematic
    calibration from the controller and generate the required .yaml file.

    Main author of the migration to yaml configs: Ludovic Delval.

    Contributors to previous versions (in no particular order):

     - Felix Messmer
     - Kelsey Hawkins
     - Wim Meeussen
     - Shaun Edwards
     - Nadia Hammoudeh Garcia
     - Dave Hershberger
     - G. vd. Hoorn
     - Philip Long
     - Dave Coleman
     - Miguel Prada
     - Mathias Luedtke
     - Marcel Schnirring
     - Felix von Drigalski
     - Felix Exner
     - Jimmy Da Silva
     - Ajit Krisshna N L
     - Muhammad Asif Rana
  -->

  <xacro:include filename="$(find ur_description)/urdf/inc/ur_transmissions.xacro" />
  <xacro:include filename="$(find ur_description)/urdf/inc/ur_common.xacro" />

  <xacro:macro name="ur_robot" params="
    prefix
    joint_limits_parameters_file
    kinematics_parameters_file
    physical_parameters_file
    visual_parameters_file
    transmission_hw_interface:=hardware_interface/PositionJointInterface
    safety_limits:=false
    safety_pos_margin:=0.15
    safety_k_position:=20"
  >
    <!-- Load configuration data from the provided .yaml files -->
    <xacro:read_model_data
      joint_limits_parameters_file="${joint_limits_parameters_file}" 
      kinematics_parameters_file="${kinematics_parameters_file}"
      physical_parameters_file="${physical_parameters_file}"
      visual_parameters_file="${visual_parameters_file}"/>

    <!-- Add URDF transmission elements (for ros_control) -->
    <xacro:ur_arm_transmission prefix="${prefix}" hw_interface="${transmission_hw_interface}" />

    <!--
      This is for compatibility reasons, as transformation between base and
      base_link was always 180 degree in the ur_description.
    -->
    <!-- TODO(cj): See if we can remove this in favor of the new base_link_inertia link. -->
    <xacro:property name="base_correction" value="${pi}" />

    <!-- links: main serial chain -->
    <link name="${prefix}base_link">
      <visual>
        <origin xyz="0 0 0" rpy="0 0 ${base_correction}"/>
        <geometry>
          <mesh filename="${base_visual_mesh}"/>
        </geometry>
        <material name="${base_visual_material_name}">
          <color rgba="${base_visual_material_color}"/>
        </material>
      </visual>
      <collision>
        <origin xyz="0 0 0" rpy="0 0 ${base_correction}"/>
        <geometry>
          <mesh filename="${base_collision_mesh}"/>
        </geometry>
      </collision>
      <xacro:cylinder_inertial radius="${base_inertia_radius}" length="${base_inertia_length}" mass="${base_mass}">
        <origin xyz="0 0 0" rpy="0 0 0" />
      </xacro:cylinder_inertial>
    </link>
    <link name="${prefix}shoulder_link">
      <visual>
        <origin xyz="0 0 0" rpy="0 0 ${pi}"/>
        <geometry>
          <mesh filename="${shoulder_visual_mesh}"/>
        </geometry>
        <material name="${shoulder_visual_material_name}">
          <color rgba="${shoulder_visual_material_color}"/>
        </material>
      </visual>
      <collision>
        <origin xyz="0 0 0" rpy="0 0 ${pi}"/>
        <geometry>
          <mesh filename="${shoulder_collision_mesh}"/>
        </geometry>
      </collision>
      <inertial>
        <mass value="${shoulder_mass}"/>
        <origin rpy="${shoulder_inertia_rotation}" xyz="${shoulder_cog}"/>
        <inertia
            ixx="${shoulder_inertia_ixx}"
            ixy="${shoulder_inertia_ixy}"
            ixz="${shoulder_inertia_ixz}"
            iyy="${shoulder_inertia_iyy}"
            iyz="${shoulder_inertia_iyz}"
            izz="${shoulder_inertia_izz}"
        />
      </inertial>
    </link>
    <link name="${prefix}upper_arm_link">
      <visual>
        <origin xyz="0 0 ${shoulder_offset}" rpy="${pi/2} 0 ${-pi/2}"/>
        <geometry>
          <mesh filename="${upper_arm_visual_mesh}"/>
        </geometry>
        <material name="${upper_arm_visual_material_name}">
          <color rgba="${upper_arm_visual_material_color}"/>
        </material>
      </visual>
      <collision>
        <origin xyz="0 0 ${shoulder_offset}" rpy="${pi/2} 0 ${-pi/2}"/>
        <geometry>
          <mesh filename="${upper_arm_collision_mesh}"/>
        </geometry>
      </collision>
      <inertial>
        <mass value="${upper_arm_mass}"/>
        <origin rpy="${upper_arm_inertia_rotation}" xyz="${upper_arm_cog}"/>
        <inertia
            ixx="${upper_arm_inertia_ixx}"
            ixy="${upper_arm_inertia_ixy}"
            ixz="${upper_arm_inertia_ixz}"
            iyy="${upper_arm_inertia_iyy}"
            iyz="${upper_arm_inertia_iyz}"
            izz="${upper_arm_inertia_izz}"
        />
      </inertial>
    </link>
    <link name="${prefix}forearm_link">
      <visual>
        <origin xyz="0 0 ${elbow_offset}" rpy="${pi/2} 0 ${-pi/2}"/>
        <geometry>
          <mesh filename="${forearm_visual_mesh}"/>
        </geometry>
        <material name="${forearm_visual_material_name}">
          <color rgba="${forearm_visual_material_color}"/>
        </material>
      </visual>
      <collision>
        <origin xyz="0 0 ${elbow_offset}" rpy="${pi/2} 0 ${-pi/2}"/>
        <geometry>
          <mesh filename="${forearm_collision_mesh}"/>
        </geometry>
      </collision>
      <inertial>
        <mass value="${forearm_mass}"/>
        <origin rpy="${forearm_inertia_rotation}" xyz="${forearm_cog}"/>
        <inertia
            ixx="${forearm_inertia_ixx}"
            ixy="${forearm_inertia_ixy}"
            ixz="${forearm_inertia_ixz}"
            iyy="${forearm_inertia_iyy}"
            iyz="${forearm_inertia_iyz}"
            izz="${forearm_inertia_izz}"
        />
      </inertial>
    </link>
    <link name="${prefix}wrist_1_link">
      <visual>
        <!-- TODO: Move this to a parameter -->
        <origin xyz="0 0 ${wrist_1_visual_offset}" rpy="${pi/2} 0 0"/>
        <geometry>
          <mesh filename="${wrist_1_visual_mesh}"/>
        </geometry>
        <material name="${wrist_1_visual_material_name}">
          <color rgba="${wrist_1_visual_material_color}"/>
        </material>
      </visual>
      <collision>
        <origin xyz="0 0 ${wrist_1_visual_offset}" rpy="${pi/2} 0 0"/>
        <geometry>
          <mesh filename="${wrist_1_collision_mesh}"/>
        </geometry>
      </collision>
      <inertial>
        <mass value="${wrist_1_mass}"/>
        <origin rpy="${wrist_1_inertia_rotation}" xyz="${wrist_1_cog}"/>
        <inertia
            ixx="${wrist_1_inertia_ixx}"
            ixy="${wrist_1_inertia_ixy}"
            ixz="${wrist_1_inertia_ixz}"
            iyy="${wrist_1_inertia_iyy}"
            iyz="${wrist_1_inertia_iyz}"
            izz="${wrist_1_inertia_izz}"
        />
      </inertial>
    </link>
    <link name="${prefix}wrist_2_link">
      <visual>
        <origin xyz="0 0 ${wrist_2_visual_offset}" rpy="0 0 0"/>
        <geometry>
          <mesh filename="${wrist_2_visual_mesh}"/>
        </geometry>
        <material name="${wrist_2_visual_material_name}">
          <color rgba="${wrist_2_visual_material_color}"/>
        </material>
      </visual>
      <collision>
        <origin xyz="0 0 ${wrist_2_visual_offset}" rpy="0 0 0"/>
        <geometry>
          <mesh filename="${wrist_2_collision_mesh}"/>
        </geometry>
      </collision>
      <inertial>
        <mass value="${wrist_2_mass}"/>
        <origin rpy="${wrist_2_inertia_rotation}" xyz="${wrist_2_cog}"/>
        <inertia
            ixx="${wrist_2_inertia_ixx}"
            ixy="${wrist_2_inertia_ixy}"
            ixz="${wrist_2_inertia_ixz}"
            iyy="${wrist_2_inertia_iyy}"
            iyz="${wrist_2_inertia_iyz}"
            izz="${wrist_2_inertia_izz}"
        />
      </inertial>
    </link>
    <link name="${prefix}wrist_3_link">
      <xacro:property name="mesh_offset" value="${wrist_3_visual_offset_xyz}" scope="parent"/>
      <xacro:if value="${wrist_3_visual_offset_xyz == ''}">
        <xacro:property name="mesh_offset" value="0 0 ${wrist_3_visual_offset}" scope="parent"/>
      </xacro:if>
      <visual>
        <origin xyz="${mesh_offset}" rpy="${pi/2} 0 0"/>
        <geometry>
          <mesh filename="${wrist_3_visual_mesh}"/>
        </geometry>
        <material name="${wrist_3_visual_material_name}">
          <color rgba="${wrist_3_visual_material_color}"/>
        </material>
      </visual>
      <collision>
        <origin xyz="${mesh_offset}" rpy="${pi/2} 0 0"/>
        <geometry>
          <mesh filename="${wrist_3_collision_mesh}"/>
        </geometry>
      </collision>
      <inertial>
        <mass value="${wrist_3_mass}"/>
        <origin rpy="${wrist_3_inertia_rotation}" xyz="${wrist_3_cog}"/>
        <inertia
            ixx="${wrist_3_inertia_ixx}"
            ixy="${wrist_3_inertia_ixy}"
            ixz="${wrist_3_inertia_ixz}"
            iyy="${wrist_3_inertia_iyy}"
            iyz="${wrist_3_inertia_iyz}"
            izz="${wrist_3_inertia_izz}"
        />
      </inertial>
    </link>

    <!-- joints: main serial chain -->
    <joint name="${prefix}shoulder_pan_joint" type="revolute">
      <parent link="${prefix}base_link" />
      <child link="${prefix}shoulder_link" />
      <origin xyz="${shoulder_x} ${shoulder_y} ${shoulder_z}" rpy="${shoulder_roll} ${shoulder_pitch} ${shoulder_yaw - base_correction}" />
      <axis xyz="0 0 1" />
      <limit lower="${shoulder_pan_lower_limit}" upper="${shoulder_pan_upper_limit}"
        effort="${shoulder_pan_effort_limit}" velocity="${shoulder_pan_velocity_limit}"/>
      <xacro:if value="${safety_limits}">
         <safety_controller soft_lower_limit="${shoulder_pan_lower_limit + safety_pos_margin}" soft_upper_limit="${shoulder_pan_upper_limit - safety_pos_margin}" k_position="${safety_k_position}" k_velocity="0.0"/>
      </xacro:if>
      <dynamics damping="0" friction="0"/>
      <!--
        NB: We use `chef_dynamics` instead of `dynamics` when doing joint-torque calculations in planning;
        `dynamics` does not have all the params we need to properly model the joint for calculating torque.
      -->
      <xacro:if value="${has_shoulder_pan_joint_dynamics}">
        <chef_dynamics coulomb_friction="${shoulder_pan_joint_coulomb_friction}"
                       viscous_damping="${shoulder_pan_joint_viscous_damping}"
                       gear_ratio="${shoulder_pan_joint_gear_ratio}"
                       rotor_inertia="${shoulder_pan_joint_rotor_inertia}"
                       reducer_inertia="${shoulder_pan_joint_reducer_inertia}"/>
      </xacro:if>
    </joint>
    <joint name="${prefix}shoulder_lift_joint" type="revolute">
      <parent link="${prefix}shoulder_link" />
      <child link="${prefix}upper_arm_link" />
      <origin xyz="${upper_arm_x} ${upper_arm_y} ${upper_arm_z}" rpy="${upper_arm_roll} ${upper_arm_pitch} ${upper_arm_yaw}" />
      <axis xyz="0 0 1" />
      <limit lower="${shoulder_lift_lower_limit}" upper="${shoulder_lift_upper_limit}"
        effort="${shoulder_lift_effort_limit}" velocity="${shoulder_lift_velocity_limit}"/>
      <xacro:if value="${safety_limits}">
         <safety_controller soft_lower_limit="${shoulder_lift_lower_limit + safety_pos_margin}" soft_upper_limit="${shoulder_lift_upper_limit - safety_pos_margin}" k_position="${safety_k_position}" k_velocity="0.0"/>
      </xacro:if>
      <dynamics damping="0" friction="0"/>
      <xacro:if value="${has_shoulder_lift_joint_dynamics}">
        <chef_dynamics coulomb_friction="${shoulder_lift_joint_coulomb_friction}"
                       viscous_damping="${shoulder_lift_joint_viscous_damping}"
                       gear_ratio="${shoulder_lift_joint_gear_ratio}"
                       rotor_inertia="${shoulder_lift_joint_rotor_inertia}"
                       reducer_inertia="${shoulder_lift_joint_reducer_inertia}"/>
      </xacro:if>
    </joint>
    <joint name="${prefix}elbow_joint" type="revolute">
      <parent link="${prefix}upper_arm_link" />
      <child link="${prefix}forearm_link" />
      <origin xyz="${forearm_x} ${forearm_y} ${forearm_z}" rpy="${forearm_roll} ${forearm_pitch} ${forearm_yaw}" />
      <axis xyz="0 0 1" />
      <limit lower="${elbow_joint_lower_limit}" upper="${elbow_joint_upper_limit}"
        effort="${elbow_joint_effort_limit}" velocity="${elbow_joint_velocity_limit}"/>
      <xacro:if value="${safety_limits}">
         <safety_controller soft_lower_limit="${elbow_joint_lower_limit + safety_pos_margin}" soft_upper_limit="${elbow_joint_upper_limit - safety_pos_margin}" k_position="${safety_k_position}" k_velocity="0.0"/>
      </xacro:if>
      <dynamics damping="0" friction="0"/>
      <xacro:if value="${has_elbow_joint_dynamics}">
        <chef_dynamics coulomb_friction="${elbow_joint_coulomb_friction}"
                       viscous_damping="${elbow_joint_viscous_damping}"
                       gear_ratio="${elbow_joint_gear_ratio}"
                       rotor_inertia="${elbow_joint_rotor_inertia}"
                       reducer_inertia="${elbow_joint_reducer_inertia}"/>
      </xacro:if>
    </joint>
    <joint name="${prefix}wrist_1_joint" type="revolute">
      <parent link="${prefix}forearm_link" />
      <child link="${prefix}wrist_1_link" />
      <origin xyz="${wrist_1_x} ${wrist_1_y} ${wrist_1_z}" rpy="${wrist_1_roll} ${wrist_1_pitch} ${wrist_1_yaw}" />
      <axis xyz="0 0 1" />
      <limit lower="${wrist_1_lower_limit}" upper="${wrist_1_upper_limit}"
        effort="${wrist_1_effort_limit}" velocity="${wrist_1_velocity_limit}"/>
      <xacro:if value="${safety_limits}">
         <safety_controller soft_lower_limit="${wrist_1_lower_limit + safety_pos_margin}" soft_upper_limit="${wrist_1_upper_limit - safety_pos_margin}" k_position="${safety_k_position}" k_velocity="0.0"/>
      </xacro:if>
      <dynamics damping="0" friction="0"/>
      <xacro:if value="${has_wrist_1_joint_dynamics}">
        <chef_dynamics coulomb_friction="${wrist_1_joint_coulomb_friction}"
                       viscous_damping="${wrist_1_joint_viscous_damping}"
                       gear_ratio="${wrist_1_joint_gear_ratio}"
                       rotor_inertia="${wrist_1_joint_rotor_inertia}"
                       reducer_inertia="${wrist_1_joint_reducer_inertia}"/>
      </xacro:if>
    </joint>
    <joint name="${prefix}wrist_2_joint" type="revolute">
      <parent link="${prefix}wrist_1_link" />
      <child link="${prefix}wrist_2_link" />
      <origin xyz="${wrist_2_x} ${wrist_2_y} ${wrist_2_z}" rpy="${wrist_2_roll} ${wrist_2_pitch} ${wrist_2_yaw}" />
      <axis xyz="0 0 1" />
      <limit lower="${wrist_2_lower_limit}" upper="${wrist_2_upper_limit}"
             effort="${wrist_2_effort_limit}" velocity="${wrist_2_velocity_limit}"/>
      <xacro:if value="${safety_limits}">
         <safety_controller soft_lower_limit="${wrist_2_lower_limit + safety_pos_margin}" soft_upper_limit="${wrist_2_upper_limit - safety_pos_margin}" k_position="${safety_k_position}" k_velocity="0.0"/>
      </xacro:if>
      <dynamics damping="0" friction="0"/>
      <xacro:if value="${has_wrist_2_joint_dynamics}">
        <chef_dynamics coulomb_friction="${wrist_2_joint_coulomb_friction}"
                       viscous_damping="${wrist_2_joint_viscous_damping}"
                       gear_ratio="${wrist_2_joint_gear_ratio}"
                       rotor_inertia="${wrist_2_joint_rotor_inertia}"
                       reducer_inertia="${wrist_2_joint_reducer_inertia}"/>
      </xacro:if>
    </joint>
    <joint name="${prefix}wrist_3_joint" type="revolute">
      <parent link="${prefix}wrist_2_link" />
      <child link="${prefix}wrist_3_link" />
      <origin xyz="${wrist_3_x} ${wrist_3_y} ${wrist_3_z}" rpy="${wrist_3_roll} ${wrist_3_pitch} ${wrist_3_yaw}" />
      <axis xyz="0 0 1" />
      <limit lower="${wrist_3_lower_limit}" upper="${wrist_3_upper_limit}"
             effort="${wrist_3_effort_limit}" velocity="${wrist_3_velocity_limit}"/>
      <xacro:if value="${safety_limits}">
         <safety_controller soft_lower_limit="${wrist_3_lower_limit + safety_pos_margin}" soft_upper_limit="${wrist_3_upper_limit - safety_pos_margin}" k_position="${safety_k_position}" k_velocity="0.0"/>
      </xacro:if>
      <dynamics damping="0" friction="0"/>
      <xacro:if value="${has_wrist_3_joint_dynamics}">
        <chef_dynamics coulomb_friction="${wrist_3_joint_coulomb_friction}"
                       viscous_damping="${wrist_3_joint_viscous_damping}"
                       gear_ratio="${wrist_3_joint_gear_ratio}"
                       rotor_inertia="${wrist_3_joint_rotor_inertia}"
                       reducer_inertia="${wrist_3_joint_reducer_inertia}"/>
      </xacro:if>
    </joint>

    <!-- ROS-Industrial 'base' frame: base_link to UR 'Base' Coordinates transform -->
    <link name="${prefix}base"/>
    <joint name="${prefix}base_link-base_fixed_joint" type="fixed">
      <!-- Note the rotation over Z of pi radians: as base_link is REP-103
           aligned (ie: has X+ forward, Y+ left and Z+ up), this is needed
           to correctly align 'base' with the 'Base' coordinate system of
           the UR controller.
      -->
      <origin xyz="0 0 0" rpy="0 0 ${base_correction}"/>
      <parent link="${prefix}base_link"/>
      <child link="${prefix}base"/>
    </joint>

    <!--
      TODO(cj): See if we can keep the flange and tool0 links and their
        corresponding joints.
    -->

    <!-- Configure self collision properties per link -->
    <!-- TODO(cj): Have callers use the ur_robot_gazebo macro instead. -->
    <gazebo reference="${prefix}shoulder_link">
      <selfCollide>true</selfCollide>
    </gazebo>
    <gazebo reference="${prefix}upper_arm_link">
      <selfCollide>true</selfCollide>
    </gazebo>
    <gazebo reference="${prefix}forearm_link">
      <selfCollide>true</selfCollide>
    </gazebo>
    <gazebo reference="${prefix}wrist_1_link">
      <selfCollide>true</selfCollide>
    </gazebo>
    <gazebo reference="${prefix}wrist_3_link">
      <selfCollide>true</selfCollide>
    </gazebo>
    <gazebo reference="${prefix}wrist_2_link">
      <selfCollide>true</selfCollide>
    </gazebo>
    <gazebo reference="${prefix}ee_link">
      <selfCollide>true</selfCollide>
    </gazebo>
  </xacro:macro>
</robot>
